2024-11-14 18:22:55.827187: I tensorflow/tsl/cuda/cudart_stub.cc:28] Could not find cuda drivers on your machine, GPU will not be used.
2024-11-14 18:23:09.409752: I tensorflow/core/platform/cpu_feature_guard.cc:182] This TensorFlow binary is optimized to use available CPU instructions in performance-critical operations.
To enable the following instructions: AVX2 FMA, in other operations, rebuild TensorFlow with the appropriate compiler flags.
2024-11-14 18:23:27.390346: W tensorflow/compiler/tf2tensorrt/utils/py_utils.cc:38] TF-TRT Warning: Could not find TensorRT
/home/sharifm/students/abdullahg/anaconda3/lib/python3.8/site-packages/transformers/utils/hub.py:128: FutureWarning: Using `TRANSFORMERS_CACHE` is deprecated and will be removed in v5 of Transformers. Use `HF_HOME` instead.
  warnings.warn(
Traceback (most recent call last):
  File "/home/sharifm/students/abdullahg/anaconda3/lib/python3.8/site-packages/transformers/utils/import_utils.py", line 1778, in _get_module
    return importlib.import_module("." + module_name, self.__name__)
  File "/home/sharifm/students/abdullahg/anaconda3/lib/python3.8/importlib/__init__.py", line 127, in import_module
    return _bootstrap._gcd_import(name[level:], package, level)
  File "<frozen importlib._bootstrap>", line 1014, in _gcd_import
  File "<frozen importlib._bootstrap>", line 991, in _find_and_load
  File "<frozen importlib._bootstrap>", line 975, in _find_and_load_unlocked
  File "<frozen importlib._bootstrap>", line 671, in _load_unlocked
  File "<frozen importlib._bootstrap_external>", line 783, in exec_module
  File "<frozen importlib._bootstrap>", line 219, in _call_with_frames_removed
  File "/home/sharifm/students/abdullahg/anaconda3/lib/python3.8/site-packages/transformers/modeling_utils.py", line 48, in <module>
    from .loss.loss_utils import LOSS_MAPPING
  File "/home/sharifm/students/abdullahg/anaconda3/lib/python3.8/site-packages/transformers/loss/loss_utils.py", line 19, in <module>
    from .loss_deformable_detr import DeformableDetrForObjectDetectionLoss, DeformableDetrForSegmentationLoss
  File "/home/sharifm/students/abdullahg/anaconda3/lib/python3.8/site-packages/transformers/loss/loss_deformable_detr.py", line 4, in <module>
    from ..image_transforms import center_to_corners_format
  File "/home/sharifm/students/abdullahg/anaconda3/lib/python3.8/site-packages/transformers/image_transforms.py", line 50, in <module>
    import tensorflow as tf
  File "/home/sharifm/students/abdullahg/anaconda3/lib/python3.8/site-packages/tensorflow/__init__.py", line 38, in <module>
    from tensorflow.python.tools import module_util as _module_util
  File "/home/sharifm/students/abdullahg/anaconda3/lib/python3.8/site-packages/tensorflow/python/__init__.py", line 45, in <module>
    from tensorflow.python.feature_column import feature_column_lib as feature_column
  File "/home/sharifm/students/abdullahg/anaconda3/lib/python3.8/site-packages/tensorflow/python/feature_column/feature_column_lib.py", line 18, in <module>
    from tensorflow.python.feature_column.feature_column import *
  File "/home/sharifm/students/abdullahg/anaconda3/lib/python3.8/site-packages/tensorflow/python/feature_column/feature_column.py", line 143, in <module>
    from tensorflow.python.layers import base
  File "/home/sharifm/students/abdullahg/anaconda3/lib/python3.8/site-packages/tensorflow/python/layers/base.py", line 16, in <module>
    from tensorflow.python.keras.legacy_tf_layers import base
  File "/home/sharifm/students/abdullahg/anaconda3/lib/python3.8/site-packages/tensorflow/python/keras/__init__.py", line 25, in <module>
    from tensorflow.python.keras import models
  File "/home/sharifm/students/abdullahg/anaconda3/lib/python3.8/site-packages/tensorflow/python/keras/models.py", line 22, in <module>
    from tensorflow.python.keras.engine import functional
  File "/home/sharifm/students/abdullahg/anaconda3/lib/python3.8/site-packages/tensorflow/python/keras/engine/functional.py", line 32, in <module>
    from tensorflow.python.keras.engine import training as training_lib
  File "/home/sharifm/students/abdullahg/anaconda3/lib/python3.8/site-packages/tensorflow/python/keras/engine/training.py", line 53, in <module>
    from tensorflow.python.keras.saving import hdf5_format
  File "/home/sharifm/students/abdullahg/anaconda3/lib/python3.8/site-packages/tensorflow/python/keras/saving/hdf5_format.py", line 37, in <module>
    import h5py
  File "/home/sharifm/students/abdullahg/anaconda3/lib/python3.8/site-packages/h5py/__init__.py", line 46, in <module>
    from ._conv import register_converters as _register_converters
  File "h5py/h5t.pxd", line 14, in init h5py._conv
  File "h5py/h5t.pyx", line 293, in init h5py.h5t
  File "/home/sharifm/students/abdullahg/anaconda3/lib/python3.8/site-packages/numpy/__init__.py", line 320, in __getattr__
    raise AttributeError("module {!r} has no attribute "
AttributeError: module 'numpy' has no attribute 'typeDict'

The above exception was the direct cause of the following exception:

Traceback (most recent call last):
  File "/home/sharifm/students/abdullahg/anaconda3/lib/python3.8/site-packages/transformers/utils/import_utils.py", line 1778, in _get_module
    return importlib.import_module("." + module_name, self.__name__)
  File "/home/sharifm/students/abdullahg/anaconda3/lib/python3.8/importlib/__init__.py", line 127, in import_module
    return _bootstrap._gcd_import(name[level:], package, level)
  File "<frozen importlib._bootstrap>", line 1014, in _gcd_import
  File "<frozen importlib._bootstrap>", line 991, in _find_and_load
  File "<frozen importlib._bootstrap>", line 975, in _find_and_load_unlocked
  File "<frozen importlib._bootstrap>", line 671, in _load_unlocked
  File "<frozen importlib._bootstrap_external>", line 783, in exec_module
  File "<frozen importlib._bootstrap>", line 219, in _call_with_frames_removed
  File "/home/sharifm/students/abdullahg/anaconda3/lib/python3.8/site-packages/transformers/integrations/integration_utils.py", line 36, in <module>
    from .. import PreTrainedModel, TFPreTrainedModel
  File "<frozen importlib._bootstrap>", line 1039, in _handle_fromlist
  File "/home/sharifm/students/abdullahg/anaconda3/lib/python3.8/site-packages/transformers/utils/import_utils.py", line 1766, in __getattr__
    module = self._get_module(self._class_to_module[name])
  File "/home/sharifm/students/abdullahg/anaconda3/lib/python3.8/site-packages/transformers/utils/import_utils.py", line 1780, in _get_module
    raise RuntimeError(
RuntimeError: Failed to import transformers.modeling_utils because of the following error (look up to see its traceback):
module 'numpy' has no attribute 'typeDict'

The above exception was the direct cause of the following exception:

Traceback (most recent call last):
  File "/home/sharifm/students/abdullahg/anaconda3/lib/python3.8/site-packages/transformers/utils/import_utils.py", line 1778, in _get_module
    return importlib.import_module("." + module_name, self.__name__)
  File "/home/sharifm/students/abdullahg/anaconda3/lib/python3.8/importlib/__init__.py", line 127, in import_module
    return _bootstrap._gcd_import(name[level:], package, level)
  File "<frozen importlib._bootstrap>", line 1014, in _gcd_import
  File "<frozen importlib._bootstrap>", line 991, in _find_and_load
  File "<frozen importlib._bootstrap>", line 975, in _find_and_load_unlocked
  File "<frozen importlib._bootstrap>", line 671, in _load_unlocked
  File "<frozen importlib._bootstrap_external>", line 783, in exec_module
  File "<frozen importlib._bootstrap>", line 219, in _call_with_frames_removed
  File "/home/sharifm/students/abdullahg/anaconda3/lib/python3.8/site-packages/transformers/trainer.py", line 42, in <module>
    from .integrations import (
  File "<frozen importlib._bootstrap>", line 1039, in _handle_fromlist
  File "/home/sharifm/students/abdullahg/anaconda3/lib/python3.8/site-packages/transformers/utils/import_utils.py", line 1766, in __getattr__
    module = self._get_module(self._class_to_module[name])
  File "/home/sharifm/students/abdullahg/anaconda3/lib/python3.8/site-packages/transformers/utils/import_utils.py", line 1780, in _get_module
    raise RuntimeError(
RuntimeError: Failed to import transformers.integrations.integration_utils because of the following error (look up to see its traceback):
Failed to import transformers.modeling_utils because of the following error (look up to see its traceback):
module 'numpy' has no attribute 'typeDict'

The above exception was the direct cause of the following exception:

Traceback (most recent call last):
  File "trainWithLSTM.py", line 2, in <module>
    from transformers import AutoTokenizer, AutoModel, Trainer, TrainingArguments
  File "<frozen importlib._bootstrap>", line 1039, in _handle_fromlist
  File "/home/sharifm/students/abdullahg/anaconda3/lib/python3.8/site-packages/transformers/utils/import_utils.py", line 1766, in __getattr__
    module = self._get_module(self._class_to_module[name])
  File "/home/sharifm/students/abdullahg/anaconda3/lib/python3.8/site-packages/transformers/utils/import_utils.py", line 1780, in _get_module
    raise RuntimeError(
RuntimeError: Failed to import transformers.trainer because of the following error (look up to see its traceback):
Failed to import transformers.integrations.integration_utils because of the following error (look up to see its traceback):
Failed to import transformers.modeling_utils because of the following error (look up to see its traceback):
module 'numpy' has no attribute 'typeDict'
slurmstepd: error: _cgroup_procs_check: failed on path (null)/cgroup.procs: No such file or directory
slurmstepd: error: Cannot write to cgroup.procs for (null)
slurmstepd: error: Unable to move pid 3546086 to init root cgroup (null)
